<?xml version="1.0"?>
<robot xmlns:xacro="http://www.ros.org/wiki/xacro" >
<xacro:include filename="inertial_macros.xacro" />

 <material name="white">
     <color rgba="1 1 1 1" />
 </material>


 <material name="black">
     <color rgba="0 0 0 1"/>
 </material>


 <!-- BASE LINK -->

 <link name="base_link">

 </link>
 
 <!-- BASE_FOOTPRINT LINK -->
<joint name="base_footprint_joint" type="fixed">
 <parent link="base_link"/>
 <child link="base_footprint"/>
 <origin xyz="0 0 0" rpy="0 0 0"/>
</joint>

<link name="base_footprint">
</link>
 


 <joint name="chassis_joint" type="fixed">

 <parent link="base_link"/>
 <child link="chassis"/>
 <origin xyz="-0.1 0 0"/>

</joint>

<link name="chassis">
 <visual>
     <origin xyz="0.125 0 0.095" rpy="0 0 0"/>
     <geometry>
         <box size="0.451 0.451 0.2"/>
     </geometry>

     <material name="white"/>
 </visual>

 <collision>
    <origin xyz="0.125 0 0.095" rpy="0 0 0"/>
    <geometry>
        <box size="0.451 0.451 0.2"/>
    </geometry>
</collision>

<xacro:inertial_box mass="200" x="0.451" y="0.451" z="0.2">
      <origin xyz="0.125 0 0.0" rpy="0 0 0"/>
  </xacro:inertial_box>

</link>

<gazebo reference="chassis">
   <material>Gazebo/White</material>
</gazebo>

<!-- LEFT WHEEL01 -->

  <joint name="left_wheel_joint01" type="continuous">
    <parent link="base_link"/>
    <child link="left_wheel01"/>
    <origin xyz="0.125 0.2 0" rpy="-${pi/2} 0 0"/>
    <axis xyz="0 0 1"/>
  </joint>

  <link name="left_wheel01">
<visual>
    <geometry>
        <cylinder length="0.04" radius="0.1" />
    </geometry>
    <material name="black"/>
</visual>

<collision>
    
    <geometry>
        <cylinder length="0.04" radius="0.1" />
    </geometry>
</collision>

<xacro:inertial_cylinder mass="0.1" length="0.05" radius="0.1">
      <origin xyz="0 0 0" rpy="0 0 0"/>
  </xacro:inertial_cylinder>

</link>

<gazebo reference="left_wheel01">
   <material>Gazebo/Black</material>
</gazebo>

<!-- LEFT WHEEL02 -->

  <joint name="left_wheel_joint02" type="continuous">
    <parent link="base_link"/>
    <child link="left_wheel02"/>
    <origin xyz="-0.1 0.2 0" rpy="-${pi/2} 0 0"/>
    <axis xyz="0 0 1"/>
  </joint>

  <link name="left_wheel02">
<visual>
    <geometry>
        <cylinder length="0.04" radius="0.1" />
    </geometry>
    <material name="black"/>
</visual>

<collision>
    
    <geometry>
        <cylinder length="0.04" radius="0.1" />
    </geometry>
</collision>

<xacro:inertial_cylinder mass="0.1" length="0.05" radius="0.1">
      <origin xyz="0 0 0" rpy="0 0 0"/>
  </xacro:inertial_cylinder>

</link>

<gazebo reference="left_wheel02">
   <material>Gazebo/Black</material>
</gazebo>

<!-- RIGHT WHEEL01 -->

<joint name="right_wheel_joint01" type="continuous">
<parent link="base_link"/>
<child link="right_wheel01"/>
<origin xyz="0.125 -0.2 0" rpy="${pi/2} 0 0"/>
<axis xyz="0 0 -1"/>
</joint>

<link name="right_wheel01">
<visual>
    <geometry>
        <cylinder length="0.04" radius="0.1" />
    </geometry>
    <material name="black"/>
</visual>

<collision>
    
    <geometry>
        <cylinder length="0.04" radius="0.1" />
    </geometry>
</collision>

<xacro:inertial_cylinder mass="0.1" length="0.05" radius="0.1">
      <origin xyz="0 0 0" rpy="0 0 0"/>
  </xacro:inertial_cylinder>
</link>

 <gazebo reference="right_wheel01">
   <material>Gazebo/Black</material>
</gazebo>

<!-- RIGHT WHEEL02 -->

<joint name="right_wheel_joint02" type="continuous">
<parent link="base_link"/>
<child link="right_wheel02"/>
<origin xyz="-0.1 -0.2 0" rpy="${pi/2} 0 0"/>
<axis xyz="0 0 -1"/>
</joint>

<link name="right_wheel02">
<visual>
    <geometry>
        <cylinder length="0.04" radius="0.1" />
    </geometry>
    <material name="black"/>
</visual>

<collision>
    <geometry>
        <cylinder length="0.04" radius="0.1" />
    </geometry>
</collision>

<xacro:inertial_cylinder mass="0.1" length="0.05" radius="0.1">
      <origin xyz="0 0 0" rpy="0 0 0"/>
  </xacro:inertial_cylinder>
</link> 

<gazebo reference="right_wheel02">
   <material>Gazebo/Black</material>
</gazebo>


<!-- CASTER WHEEL 

<joint name="caster_wheel_joint" type="fixed">
<parent link="chassis"/>
<child link="caster_wheel"/>
<origin xyz="0.24 0 0" rpy="0 0 0"/>
</joint>

<link name="caster_wheel">
<visual>
    <geometry>
        <sphere radius="0.05" />
    </geometry>
    <material name="black"/>
</visual>

<collision>
    <origin xyz="0.24 0 0" rpy="0 0 0"/>
    <geometry>
     <sphere radius="0.05" />
    </geometry>
</collision>

<xacro:inertial_sphere mass="0.1" radius="0.05">
      <origin xyz="0 0 0" rpy="0 0 0"/>
  </xacro:inertial_sphere>

</link>
-->
 
</robot>